class Test{
    try{}
    catch(ArithmaticException e){}
    catch(Exception ae){}
}